2017-09-04 17:42:19.061 +02:00 [Information] Request starting HTTP/1.1 GET http://localhost:22608/api/assignments/6  
2017-09-04 17:42:19.943 +02:00 [Information] Request finished in 941.9895ms 404 
2017-09-04 17:42:20.010 +02:00 [Information] Request starting HTTP/1.1 GET http://localhost:22608/favicon.ico  
2017-09-04 17:42:20.014 +02:00 [Information] Request finished in 3.9577ms 404 
2017-09-04 17:42:32.666 +02:00 [Information] Request starting HTTP/1.1 GET http://localhost:22608/assignments/6  
2017-09-04 17:42:33.102 +02:00 [Information] Executing action method "webs2_api.Controllers.AssignmentsController.Get (Webdictaat.Apis.Databases)" with arguments (["6"]) - ModelState is Valid
2017-09-04 17:42:34.413 +02:00 [Error] An exception occurred in the database while iterating the results of a query.

MySql.Data.MySqlClient.MySqlException: Authentication to host 'databases.aii.avans.nl' for user 'bjgelens' using method 'mysql_native_password' failed with message: Access denied for user 'bjgelens'@'145.49.111.89' (using password: YES) ---> MySql.Data.MySqlClient.MySqlException: Access denied for user 'bjgelens'@'145.49.111.89' (using password: YES)
   at MySql.Data.MySqlClient.MySqlStream.ReadPacket()
   at MySql.Data.MySqlClient.NativeDriver.ReadPacket()
   at MySql.Data.MySqlClient.Authentication.MySqlAuthenticationPlugin.ReadPacket()
   --- End of inner exception stack trace ---
   at MySql.Data.MySqlClient.Authentication.MySqlAuthenticationPlugin.AuthenticationFailed(Exception ex)
   at MySql.Data.MySqlClient.Authentication.MySqlAuthenticationPlugin.ReadPacket()
   at MySql.Data.MySqlClient.Authentication.MySqlAuthenticationPlugin.Authenticate(Boolean reset)
   at MySql.Data.MySqlClient.NativeDriver.Authenticate(String authMethod, Boolean reset)
   at MySql.Data.MySqlClient.NativeDriver.Open()
   at MySql.Data.MySqlClient.Driver.Open()
   at MySql.Data.MySqlClient.Driver.Create(MySqlConnectionStringBuilder settings)
   at MySql.Data.MySqlClient.MySqlPool.CreateNewPooledConnection()
   at MySql.Data.MySqlClient.MySqlPool.GetPooledConnection()
   at MySql.Data.MySqlClient.MySqlPool.TryToGetDriver()
   at MySql.Data.MySqlClient.MySqlPool.GetConnection()
   at MySql.Data.MySqlClient.MySqlConnection.Open()
   at Microsoft.EntityFrameworkCore.Storage.RelationalConnection.Open()
   at Microsoft.EntityFrameworkCore.Query.Internal.QueryingEnumerable.Enumerator.MoveNext()
   at Microsoft.EntityFrameworkCore.Query.QueryMethodProvider.<_ShapedQuery>d__3`1.MoveNext()
   at System.Linq.Enumerable.FirstOrDefault[TSource](IEnumerable`1 source)
   at lambda_method(Closure , QueryContext )
   at Microsoft.EntityFrameworkCore.Query.Internal.QueryCompiler.<>c__DisplayClass20_0`1.<CompileQueryCore>b__0(QueryContext qc)
2017-09-04 17:42:39.272 +02:00 [Error] Connection id ""0HL7JLE37TPAO"": An unhandled exception was thrown by the application.
MySql.Data.MySqlClient.MySqlException: Authentication to host 'databases.aii.avans.nl' for user 'bjgelens' using method 'mysql_native_password' failed with message: Access denied for user 'bjgelens'@'145.49.111.89' (using password: YES) ---> MySql.Data.MySqlClient.MySqlException: Access denied for user 'bjgelens'@'145.49.111.89' (using password: YES)
   at MySql.Data.MySqlClient.MySqlStream.ReadPacket()
   at MySql.Data.MySqlClient.NativeDriver.ReadPacket()
   at MySql.Data.MySqlClient.Authentication.MySqlAuthenticationPlugin.ReadPacket()
   --- End of inner exception stack trace ---
   at MySql.Data.MySqlClient.Authentication.MySqlAuthenticationPlugin.AuthenticationFailed(Exception ex)
   at MySql.Data.MySqlClient.Authentication.MySqlAuthenticationPlugin.ReadPacket()
   at MySql.Data.MySqlClient.Authentication.MySqlAuthenticationPlugin.Authenticate(Boolean reset)
   at MySql.Data.MySqlClient.NativeDriver.Authenticate(String authMethod, Boolean reset)
   at MySql.Data.MySqlClient.NativeDriver.Open()
   at MySql.Data.MySqlClient.Driver.Open()
   at MySql.Data.MySqlClient.Driver.Create(MySqlConnectionStringBuilder settings)
   at MySql.Data.MySqlClient.MySqlPool.CreateNewPooledConnection()
   at MySql.Data.MySqlClient.MySqlPool.GetPooledConnection()
   at MySql.Data.MySqlClient.MySqlPool.TryToGetDriver()
   at MySql.Data.MySqlClient.MySqlPool.GetConnection()
   at MySql.Data.MySqlClient.MySqlConnection.Open()
   at Microsoft.EntityFrameworkCore.Storage.RelationalConnection.Open()
   at Microsoft.EntityFrameworkCore.Query.Internal.QueryingEnumerable.Enumerator.MoveNext()
   at Microsoft.EntityFrameworkCore.Query.QueryMethodProvider.<_ShapedQuery>d__3`1.MoveNext()
   at System.Linq.Enumerable.FirstOrDefault[TSource](IEnumerable`1 source)
   at lambda_method(Closure , QueryContext )
   at Microsoft.EntityFrameworkCore.Query.Internal.QueryCompiler.<>c__DisplayClass20_0`1.<CompileQueryCore>b__0(QueryContext qc)
   at System.Linq.Queryable.FirstOrDefault[TSource](IQueryable`1 source)
   at webs2_api.Controllers.AssignmentsController.Get(Int32 assignmentId) in C:\Users\Stijn\Documents\GitHub\Webdictaat\Webdictaat.Apis.Databases\src\Webdictaat.Apis.Databases\Controllers\AssignmentsController.cs:line 38
   at lambda_method(Closure , Object , Object[] )
   at Microsoft.AspNetCore.Mvc.Internal.ControllerActionInvoker.<InvokeActionFilterAsync>d__28.MoveNext()
--- End of stack trace from previous location where exception was thrown ---
   at Microsoft.AspNetCore.Mvc.Internal.ControllerActionInvoker.<InvokeAsync>d__18.MoveNext()
--- End of stack trace from previous location where exception was thrown ---
   at System.Runtime.CompilerServices.TaskAwaiter.ThrowForNonSuccess(Task task)
   at System.Runtime.CompilerServices.TaskAwaiter.HandleNonSuccessAndDebuggerNotification(Task task)
   at Microsoft.AspNetCore.Builder.RouterMiddleware.<Invoke>d__4.MoveNext()
--- End of stack trace from previous location where exception was thrown ---
   at System.Runtime.CompilerServices.TaskAwaiter.ThrowForNonSuccess(Task task)
   at System.Runtime.CompilerServices.TaskAwaiter.HandleNonSuccessAndDebuggerNotification(Task task)
   at Microsoft.AspNetCore.Cors.Infrastructure.CorsMiddleware.<Invoke>d__7.MoveNext()
--- End of stack trace from previous location where exception was thrown ---
   at System.Runtime.CompilerServices.TaskAwaiter.ThrowForNonSuccess(Task task)
   at System.Runtime.CompilerServices.TaskAwaiter.HandleNonSuccessAndDebuggerNotification(Task task)
   at Microsoft.ApplicationInsights.AspNetCore.ExceptionTrackingMiddleware.<Invoke>d__4.MoveNext()
--- End of stack trace from previous location where exception was thrown ---
   at System.Runtime.CompilerServices.TaskAwaiter.ThrowForNonSuccess(Task task)
   at System.Runtime.CompilerServices.TaskAwaiter.HandleNonSuccessAndDebuggerNotification(Task task)
   at Microsoft.ApplicationInsights.AspNetCore.RequestTrackingMiddleware.<Invoke>d__4.MoveNext()
--- End of stack trace from previous location where exception was thrown ---
   at System.Runtime.CompilerServices.TaskAwaiter.ThrowForNonSuccess(Task task)
   at System.Runtime.CompilerServices.TaskAwaiter.HandleNonSuccessAndDebuggerNotification(Task task)
   at Microsoft.AspNetCore.Server.IISIntegration.IISMiddleware.<Invoke>d__8.MoveNext()
--- End of stack trace from previous location where exception was thrown ---
   at System.Runtime.CompilerServices.TaskAwaiter.ThrowForNonSuccess(Task task)
   at System.Runtime.CompilerServices.TaskAwaiter.HandleNonSuccessAndDebuggerNotification(Task task)
   at Microsoft.AspNetCore.Hosting.Internal.RequestServicesContainerMiddleware.<Invoke>d__3.MoveNext()
--- End of stack trace from previous location where exception was thrown ---
   at System.Runtime.CompilerServices.TaskAwaiter.ThrowForNonSuccess(Task task)
   at System.Runtime.CompilerServices.TaskAwaiter.HandleNonSuccessAndDebuggerNotification(Task task)
   at Microsoft.AspNetCore.Server.Kestrel.Internal.Http.Frame`1.<RequestProcessingAsync>d__2.MoveNext()
2017-09-04 17:42:39.282 +02:00 [Information] Request finished in 6615.9927ms 200 
